<?xml version="1.0" ?>
<robot xmlns:xacro="http://ros.org/wiki/xacro">

  <!-- Much of the following Kobuki description is taken from https://github.com/yujinrobot/kobuki/blob/23748ed3dfb082831ca8eaaef1a0b08588dbcb65/kobuki_description/urdf/kobuki.urdf.xacro -->
  <!-- It has been modified to include the robot_name as a prefix to the links -->
  <!-- The kobuki_description package is distributed under the 3-Clause BSD License, but no license file was found in the package. -->
  <!-- The license from the kobuki_node package is given from https://github.com/yujinrobot/kobuki/blob/8f2fa7b9e5e98c503ba468602c3a5dd9be68fc26/kobuki_node/LICENSE below: -->
  <!--
    # Software License Agreement (BSD License)
    #
    # Copyright (c) 2012 Yujin Robot, Daniel Stonier, Jorge Santos,
    # Marcus Liebhardt, Younghun Ju, Jihoon Lee
    # All rights reserved.
    #
    # Redistribution and use in source and binary forms, with or without
    # modification, are permitted provided that the following conditions
    # are met:
    #
    #    * Redistributions of source code must retain the above copyright
    #        notice, this list of conditions and the following disclaimer.
    #    * Redistributions in binary form must reproduce the above
    #        copyright notice, this list of conditions and the following
    #        disclaimer in the documentation and/or other materials provided
    #        with the distribution.
    #    * Neither the name of Yujin Robot nor the names of its
    #        contributors may be used to endorse or promote products derived
    #        from this software without specific prior written permission.
    #
    # THIS SOFTWARE IS PROVIDED BY THE COPYRIGHT HOLDERS AND CONTRIBUTORS
    # "AS IS" AND ANY EXPRESS OR IMPLIED WARRANTIES, INCLUDING, BUT NOT
    # LIMITED TO, THE IMPLIED WARRANTIES OF MERCHANTABILITY AND FITNESS
    # FOR A PARTICULAR PURPOSE ARE DISCLAIMED. IN NO EVENT SHALL THE
    # COPYRIGHT OWNER OR CONTRIBUTORS BE LIABLE FOR ANY DIRECT, INDIRECT,
    # INCIDENTAL, SPECIAL, EXEMPLARY, OR CONSEQUENTIAL DAMAGES (INCLUDING,
    # BUT NOT LIMITED TO, PROCUREMENT OF SUBSTITUTE GOODS OR SERVICES;
    # LOSS OF USE, DATA, OR PROFITS; OR BUSINESS INTERRUPTION) HOWEVER
    # CAUSED AND ON ANY THEORY OF LIABILITY, WHETHER IN CONTRACT, STRICT
    # LIABILITY, OR TORT (INCLUDING NEGLIGENCE OR OTHERWISE) ARISING IN
    # ANY WAY OUT OF THE USE OF THIS SOFTWARE, EVEN IF ADVISED OF THE
    # POSSIBILITY OF SUCH DAMAGE.
  -->

  <joint name="base_joint" type="fixed">
    <origin rpy="0 0 0" xyz="0 0 0.0102"/>
    <parent link="$(arg robot_name)/base_footprint"/>
    <child link="$(arg robot_name)/base_link"/>
  </joint>

  <link name="$(arg robot_name)/base_link">
    <visual>
      <origin rpy="0 0 0" xyz="0.001 0 0.05199"/>
      <geometry>
        <mesh filename="package://interbotix_xslocobot_descriptions/meshes/locobot_meshes/kobuki_version/kobuki.dae"/>
      </geometry>
    </visual>
    <collision>
      <origin rpy="0 0 0" xyz="0.0 0 0.05949"/>
      <geometry>
        <cylinder length="0.10938" radius="0.178"/>
      </geometry>
    </collision>
    <inertial>
      <origin rpy="0 0 0" xyz="0.01 0 0"/>
      <mass value="2.4"/>
      <inertia ixx="0.019995" ixy="0.0" ixz="0.0" iyy="0.019995" iyz="0.0" izz="0.03675"/>
    </inertial>
  </link>

  <joint name="wheel_left_joint" type="continuous">
    <axis xyz="0 0 1"/>
    <origin rpy="-1.57079632679 0 0" xyz="0.00 0.115 0.0250"/>
    <parent link="$(arg robot_name)/base_link"/>
    <child link="$(arg robot_name)/wheel_left_link"/>
  </joint>

  <transmission name="trans_wheel_left_joint">
    <type>transmission_interface/SimpleTransmission</type>
    <joint name="wheel_left_joint">
      <hardwareInterface>hardware_interface/EffortJointInterface</hardwareInterface>
    </joint>
    <actuator name="wheel_left_joint_motor">
      <mechanicalReduction>1</mechanicalReduction>
    </actuator>
  </transmission>

  <link name="$(arg robot_name)/wheel_left_link">
    <visual>
      <origin rpy="0 0 0" xyz="0 0 0"/>
      <geometry>
        <mesh filename="package://interbotix_xslocobot_descriptions/meshes/locobot_meshes/kobuki_version/kobuki_wheel.dae"/>
      </geometry>
    </visual>
    <collision>
      <geometry>
        <cylinder length="0.0206" radius="0.0352"/>
      </geometry>
        <origin rpy="0 0 0" xyz="0 0 0"/>
    </collision>
    <inertial>
      <origin xyz="0 0 0"/>
      <mass value="0.01"/>
      <inertia ixx="0.001" ixy="0.0" ixz="0.0" iyy="0.001" iyz="0.0" izz="0.001"/>
    </inertial>
  </link>

  <joint name="wheel_right_joint" type="continuous">
    <axis xyz="0 0 1"/>
    <origin rpy="-1.57079632679 0 0" xyz="0.00 -0.115 0.0250"/>
    <parent link="$(arg robot_name)/base_link"/>
    <child link="$(arg robot_name)/wheel_right_link"/>
  </joint>

  <transmission name="trans_wheel_right_joint">
    <type>transmission_interface/SimpleTransmission</type>
    <joint name="wheel_right_joint">
      <hardwareInterface>hardware_interface/EffortJointInterface</hardwareInterface>
    </joint>
    <actuator name="wheel_right_joint_motor">
      <mechanicalReduction>1</mechanicalReduction>
    </actuator>
  </transmission>

  <link name="$(arg robot_name)/wheel_right_link">
    <visual>
      <origin rpy="0 0 0" xyz="0 0 0"/>
      <geometry>
        <mesh filename="package://interbotix_xslocobot_descriptions/meshes/locobot_meshes/kobuki_version/kobuki_wheel.dae"/>
      </geometry>
    </visual>
    <collision>
      <origin rpy="0 0 0" xyz="0 0 0"/>
      <geometry>
        <cylinder length="0.0206" radius="0.0350"/>
      </geometry>
    </collision>
    <inertial>
      <origin xyz="0 0 0"/>
      <mass value="0.01"/>
      <inertia ixx="0.001" ixy="0.0" ixz="0.0" iyy="0.001" iyz="0.0" izz="0.001"/>
    </inertial>
  </link>

  <joint name="caster_front_joint" type="fixed">
    <origin rpy="-1.57079632679 0 0" xyz="0.115 0.0 0.007"/>
    <parent link="$(arg robot_name)/base_link"/>
    <child link="$(arg robot_name)/caster_front_link"/>
  </joint>

  <link name="$(arg robot_name)/caster_front_link">
    <collision>
      <origin rpy="0 0 0" xyz="0 0 0"/>
      <geometry>
        <cylinder length="0.0176" radius="0.017"/>
      </geometry>
    </collision>
    <inertial>
      <origin xyz="0 0 0"/>
      <mass value="0.01"/>
      <inertia ixx="0.001" ixy="0.0" ixz="0.0" iyy="0.001" iyz="0.0" izz="0.001"/>
    </inertial>
  </link>

  <joint name="caster_back_joint" type="fixed">
    <origin rpy="-1.57079632679 0 0" xyz="-0.135 0.0 0.009"/>
    <parent link="$(arg robot_name)/base_link"/>
    <child link="$(arg robot_name)/caster_back_link"/>
  </joint>

  <link name="$(arg robot_name)/caster_back_link">
    <collision>
      <origin rpy="0 0 0" xyz="0 0 0"/>
      <geometry>
        <cylinder length="0.0176" radius="0.017"/>
      </geometry>
    </collision>
    <inertial>
      <origin xyz="0 0 0"/>
      <mass value="0.01"/>
      <inertia ixx="0.001" ixy="0.0" ixz="0.0" iyy="0.001" iyz="0.0" izz="0.001"/>
    </inertial>
  </link>

  <joint name="gyro_joint" type="fixed">
    <origin rpy="0 0 0" xyz="0.056 0.062 0.0202"/>
    <parent link="$(arg robot_name)/base_link"/>
    <child link="$(arg robot_name)/gyro_link"/>
  </joint>

  <link name="$(arg robot_name)/gyro_link">
    <inertial>
      <origin rpy="0 0 0" xyz="0 0 0"/>
      <mass value="0.001"/>
      <inertia ixx="0.0001" ixy="0" ixz="0" iyy="0.000001" iyz="0" izz="0.0001"/>
    </inertial>
  </link>

  <joint name="cliff_sensor_left_joint" type="fixed">
    <origin rpy="0 1.57079632679 0" xyz="0.08734 0.13601 0.0214"/>
    <parent link="$(arg robot_name)/base_link"/>
    <child link="$(arg robot_name)/cliff_sensor_left_link"/>
  </joint>

  <link name="$(arg robot_name)/cliff_sensor_left_link">
    <inertial>
      <mass value="0.0001"/>
      <origin xyz="0 0 0"/>
      <inertia ixx="0.0001" ixy="0.0" ixz="0.0" iyy="0.0001" iyz="0.0" izz="0.0001"/>
    </inertial>
  </link>

  <joint name="cliff_sensor_right_joint" type="fixed">
    <origin rpy="0 1.57079632679 0" xyz="0.085 -0.13601 0.0214"/>
    <parent link="$(arg robot_name)/base_link"/>
    <child link="$(arg robot_name)/cliff_sensor_right_link"/>
  </joint>

  <link name="$(arg robot_name)/cliff_sensor_right_link">
    <inertial>
      <origin xyz="0 0 0"/>
      <mass value="0.0001"/>
      <inertia ixx="0.0001" ixy="0.0" ixz="0.0" iyy="0.0001" iyz="0.0" izz="0.0001"/>
    </inertial>
  </link>

  <joint name="cliff_sensor_front_joint" type="fixed">
    <origin rpy="0 1.57079632679 0" xyz="0.156 0.00 0.0214"/>
    <parent link="$(arg robot_name)/base_link"/>
    <child link="$(arg robot_name)/cliff_sensor_front_link"/>
  </joint>

  <link name="$(arg robot_name)/cliff_sensor_front_link">
    <inertial>
      <mass value="0.0001"/>
      <origin xyz="0 0 0"/>
      <inertia ixx="0.0001" ixy="0.0" ixz="0.0" iyy="0.0001" iyz="0.0" izz="0.0001"/>
    </inertial>
  </link>

</robot>
