<?xml version="1.0" ?>
<robot xmlns:xacro="http://ros.org/wiki/xacro">

  <xacro:macro name="pan_and_tilt" params="*origin">

    <joint name="pan" type="revolute">
      <axis xyz="0 0 1"/>
      <limit effort="2" lower="${-pi/2}" upper="${pi/2}" velocity="${pi}"/>
      <xacro:insert_block name="origin"/>
      <parent link="$(arg robot_name)/camera_tower_link"/>
      <child link="$(arg robot_name)/pan_link"/>
    </joint>

    <transmission name="trans_pan">
      <type>transmission_interface/SimpleTransmission</type>
      <joint name="pan">
        <hardwareInterface>hardware_interface/EffortJointInterface</hardwareInterface>
      </joint>
      <actuator name="pan_motor">
        <mechanicalReduction>1</mechanicalReduction>
      </actuator>
    </transmission>

    <link name="$(arg robot_name)/pan_link">
      <visual>
        <origin rpy="0 0 ${pi/2}" xyz="0 0 0"/>
        <geometry>
          <mesh filename="package://interbotix_xslocobot_descriptions/meshes/locobot_meshes/locobot_pan.stl" scale="0.001 0.001 0.001"/>
        </geometry>
        <material name="interbotix_black"/>
      </visual>
      <collision>
        <origin rpy="0 0 ${pi/2}" xyz="0 0 0"/>
        <geometry>
          <mesh filename="package://interbotix_xslocobot_descriptions/meshes/locobot_meshes/locobot_pan.stl" scale="0.001 0.001 0.001"/>
        </geometry>
      </collision>
      <inertial>
        <origin rpy="0 0 ${pi/2}" xyz="0.012 0.000496 0.018504"/>
        <mass value="0.098997"/>
        <inertia ixx="0.0000276300" ixy="0.0000000418" ixz="0.0000005145" iyy="0.0000204300" iyz="-0.0000000421" izz="0.0000276300"/>
      </inertial>
    </link>

    <joint name="tilt" type="revolute">
      <axis xyz="0 1 0"/>
      <limit effort="2" lower="${-pi/2}" upper="${radians(75)}" velocity="${pi}"/>
      <origin rpy="0 0 0" xyz="0.025034 0 0.019"/>
      <parent link="$(arg robot_name)/pan_link"/>
      <child link="$(arg robot_name)/tilt_link"/>
    </joint>

    <transmission name="trans_tilt">
      <type>transmission_interface/SimpleTransmission</type>
      <joint name="tilt">
        <hardwareInterface>hardware_interface/EffortJointInterface</hardwareInterface>
      </joint>
      <actuator name="tilt_motor">
        <mechanicalReduction>1</mechanicalReduction>
      </actuator>
    </transmission>

    <link name="$(arg robot_name)/tilt_link">
      <visual>
        <origin rpy="0 0 ${pi/2}" xyz="0 0 0"/>
        <geometry>
          <mesh filename="package://interbotix_xslocobot_descriptions/meshes/locobot_meshes/locobot_tilt.stl" scale="0.001 0.001 0.001"/>
        </geometry>
        <material name="interbotix_black"/>
      </visual>
      <collision>
        <origin rpy="0 0 ${pi/2}" xyz="0 0 0"/>
        <geometry>
          <mesh filename="package://interbotix_xslocobot_descriptions/meshes/locobot_meshes/locobot_tilt.stl" scale="0.001 0.001 0.001"/>
        </geometry>
      </collision>
      <inertial>
        <origin rpy="0 0 ${pi/2}" xyz="0.0237737000 -0.0000016331 0.0000077432"/>
        <mass value="0.019845"/>
        <inertia ixx="0.0000021677" ixy="0.0000000000" ixz="0.0000000001" iyy="0.0000063634" iyz="0.0000000003" izz="0.0000066157"/>
      </inertial>
    </link>

    <joint name="camera" type="fixed">
      <origin rpy="0 0 0" xyz="0.05318 0.0175 0.000009"/>
      <parent link="$(arg robot_name)/tilt_link"/>
      <child link="$(arg robot_name)/camera_link"/>
    </joint>

    <link name="$(arg robot_name)/camera_link">
      <visual>
        <origin rpy="0 0 0" xyz="0 0 0"/>
        <geometry>
          <mesh filename="package://interbotix_xslocobot_descriptions/meshes/locobot_meshes/locobot_camera.stl" scale="0.001 0.001 0.001"/>
        </geometry>
        <material name="">
          <color rgba="0.55 0.55 0.55 1"/>
        </material>
      </visual>
      <collision>
        <origin rpy="0 0 0" xyz="0 0 0"/>
        <geometry>
          <mesh filename="package://interbotix_xslocobot_descriptions/meshes/locobot_meshes/locobot_camera.stl" scale="0.001 0.001 0.001"/>
        </geometry>
      </collision>
      <inertial>
        <origin rpy="0 0 0" xyz="-0.008972 -0.015818 0.000003"/>
        <mass value="0.072"/>
        <inertia ixx="0.0000465400" ixy="0.0000003028" ixz="0.0000000245" iyy="0.0000069128" iyz="0.0000000248" izz="0.0000468600"/>
      </inertial>
    </link>

  </xacro:macro>

</robot>
