<?xml version="1.0" ?>
<!-- =================================================================================== -->
<!-- |    This document was autogenerated by xacro from /home/sebastian/interbotix_ws/src/interbotix_ros_rovers/interbotix_ros_xslocobots/interbotix_xslocobot_descriptions/urdf/wx250s.urdf.xacro | -->
<!-- |    EDITING THIS FILE BY HAND IS NOT RECOMMENDED                                 | -->
<!-- =================================================================================== -->
<robot name="mobile_wx250s">
  <joint name="arm_base_link_joint" type="fixed">
    <axis xyz="0 0 0"/>
    <origin rpy="0 0 0" xyz="0.097277 0 0.0095"/>
    <parent link="locobot/plate_link"/>
    <child link="locobot/arm_base_link"/>
  </joint>
  <link name="locobot/arm_base_link">
    <visual>
      <origin rpy="1.5707963267948966 0 1.5707963267948966" xyz="-0.095773 0 -0.10565023"/>
      <geometry>
        <mesh filename="package://interbotix_xslocobot_descriptions/meshes/mobile_wx250s_meshes/mobile_wx250s_1_base.stl" scale="0.001 0.001 0.001"/>
      </geometry>
      <material name="interbotix_black"/>
    </visual>
    <collision>
      <origin rpy="1.5707963267948966 0 1.5707963267948966" xyz="-0.095773 0 -0.10565023"/>
      <geometry>
        <mesh filename="package://interbotix_xslocobot_descriptions/meshes/mobile_wx250s_meshes/mobile_wx250s_1_base.stl" scale="0.001 0.001 0.001"/>
      </geometry>
    </collision>
    <inertial>
      <origin rpy="1.5707963267948966 0 1.5707963267948966" xyz="-0.0001350000 -0.0000266286 0.0338755000"/>
      <mass value="0.379673"/>
      <inertia ixx="0.0004351000" ixy="0.0000000707" ixz="0.0000000266" iyy="0.0004452000" iyz="-0.0000022881" izz="0.0005731000"/>
    </inertial>
  </link>
  <joint name="waist" type="revolute">
    <axis xyz="0 0 1"/>
    <limit effort="10" lower="-3.141592653589793" upper="3.141592653589793" velocity="3.141592653589793"/>
    <origin rpy="0 0 0" xyz="0 0 0.066175"/>
    <parent link="locobot/arm_base_link"/>
    <child link="locobot/shoulder_link"/>
    <dynamics friction="0.1"/>
  </joint>
  <transmission name="trans_waist">
    <type>transmission_interface/SimpleTransmission</type>
    <joint name="waist">
      <hardwareInterface>hardware_interface/EffortJointInterface</hardwareInterface>
    </joint>
    <actuator name="waist_motor">
      <mechanicalReduction>1</mechanicalReduction>
    </actuator>
  </transmission>
  <link name="locobot/shoulder_link">
    <visual>
      <origin rpy="0 0 1.5707963267948966" xyz="0 0 -0.003"/>
      <geometry>
        <mesh filename="package://interbotix_xslocobot_descriptions/meshes/mobile_wx250s_meshes/mobile_wx250s_2_shoulder.stl" scale="0.001 0.001 0.001"/>
      </geometry>
      <material name="interbotix_black"/>
    </visual>
    <collision>
      <origin rpy="0 0 1.5707963267948966" xyz="0 0 -0.003"/>
      <geometry>
        <mesh filename="package://interbotix_xslocobot_descriptions/meshes/mobile_wx250s_meshes/mobile_wx250s_2_shoulder.stl" scale="0.001 0.001 0.001"/>
      </geometry>
    </collision>
    <inertial>
      <origin rpy="0 0 1.5707963267948966" xyz="0.0000223482 0.0000414609 0.0066287000"/>
      <mass value="0.480879"/>
      <inertia ixx="0.0003790000" ixy="0.0000000022" ixz="-0.0000003561" iyy="0.0005557000" iyz="0.0000012245" izz="0.0005889000"/>
    </inertial>
  </link>
  <joint name="shoulder" type="revolute">
    <axis xyz="0 1 0"/>
    <limit effort="20" lower="-1.8849555921538759" upper="1.9896753472735358" velocity="3.141592653589793"/>
    <origin rpy="0 0 0" xyz="0 0 0.03865"/>
    <parent link="locobot/shoulder_link"/>
    <child link="locobot/upper_arm_link"/>
    <dynamics friction="0.1"/>
  </joint>
  <transmission name="trans_shoulder">
    <type>transmission_interface/SimpleTransmission</type>
    <joint name="shoulder">
      <hardwareInterface>hardware_interface/EffortJointInterface</hardwareInterface>
    </joint>
    <actuator name="shoulder_motor">
      <mechanicalReduction>1</mechanicalReduction>
    </actuator>
  </transmission>
  <link name="locobot/upper_arm_link">
    <visual>
      <origin rpy="0 0 1.5707963267948966" xyz="0 0 0"/>
      <geometry>
        <mesh filename="package://interbotix_xslocobot_descriptions/meshes/mobile_wx250s_meshes/mobile_wx250s_3_upper_arm.stl" scale="0.001 0.001 0.001"/>
      </geometry>
      <material name="interbotix_black"/>
    </visual>
    <collision>
      <origin rpy="0 0 1.5707963267948966" xyz="0 0 0"/>
      <geometry>
        <mesh filename="package://interbotix_xslocobot_descriptions/meshes/mobile_wx250s_meshes/mobile_wx250s_3_upper_arm.stl" scale="0.001 0.001 0.001"/>
      </geometry>
    </collision>
    <inertial>
      <origin rpy="0 0 1.5707963267948966" xyz="0.0171605000 0.0000002725 0.1913230000"/>
      <mass value="0.430811"/>
      <inertia ixx="0.0034630000" ixy="-0.0000000001" ixz="-0.0000000002" iyy="0.0035870000" iyz="0.0004272000" izz="0.0004566000"/>
    </inertial>
  </link>
  <joint name="elbow" type="revolute">
    <axis xyz="0 1 0"/>
    <limit effort="15" lower="-2.1467549799530254" upper="1.6057029118347832" velocity="3.141592653589793"/>
    <origin rpy="0 0 0" xyz="0.04975 0 0.25"/>
    <parent link="locobot/upper_arm_link"/>
    <child link="locobot/upper_forearm_link"/>
    <dynamics friction="0.1"/>
  </joint>
  <transmission name="trans_elbow">
    <type>transmission_interface/SimpleTransmission</type>
    <joint name="elbow">
      <hardwareInterface>hardware_interface/EffortJointInterface</hardwareInterface>
    </joint>
    <actuator name="elbow_motor">
      <mechanicalReduction>1</mechanicalReduction>
    </actuator>
  </transmission>
  <link name="locobot/upper_forearm_link">
    <visual>
      <origin rpy="0 0 0" xyz="0 0 0"/>
      <geometry>
        <mesh filename="package://interbotix_xslocobot_descriptions/meshes/mobile_wx250s_meshes/mobile_wx250s_4_upper_forearm.stl" scale="0.001 0.001 0.001"/>
      </geometry>
      <material name="interbotix_black"/>
    </visual>
    <collision>
      <origin rpy="0 0 0" xyz="0 0 0"/>
      <geometry>
        <mesh filename="package://interbotix_xslocobot_descriptions/meshes/mobile_wx250s_meshes/mobile_wx250s_4_upper_forearm.stl" scale="0.001 0.001 0.001"/>
      </geometry>
    </collision>
    <inertial>
      <origin rpy="0 0 0" xyz="0.1079630000 0.0001158760 0"/>
      <mass value="0.234589"/>
      <inertia ixx="0.0000397100" ixy="0.0000023528" ixz="0" iyy="0.0008878000" iyz="0" izz="0.0008880000"/>
    </inertial>
  </link>
  <joint name="forearm_roll" type="revolute">
    <axis xyz="1 0 0"/>
    <limit effort="2" lower="-3.141592653589793" upper="3.141592653589793" velocity="3.141592653589793"/>
    <origin rpy="0 0 0" xyz="0.175 0 0"/>
    <parent link="locobot/upper_forearm_link"/>
    <child link="locobot/lower_forearm_link"/>
    <dynamics friction="0.1"/>
  </joint>
  <transmission name="trans_forearm_roll">
    <type>transmission_interface/SimpleTransmission</type>
    <joint name="forearm_roll">
      <hardwareInterface>hardware_interface/EffortJointInterface</hardwareInterface>
    </joint>
    <actuator name="forearm_roll_motor">
      <mechanicalReduction>1</mechanicalReduction>
    </actuator>
  </transmission>
  <link name="locobot/lower_forearm_link">
    <visual>
      <origin rpy="3.141592653589793 0 0" xyz="0 0 0"/>
      <geometry>
        <mesh filename="package://interbotix_xslocobot_descriptions/meshes/mobile_wx250s_meshes/mobile_wx250s_5_lower_forearm.stl" scale="0.001 0.001 0.001"/>
      </geometry>
      <material name="interbotix_black"/>
    </visual>
    <collision>
      <origin rpy="3.141592653589793 0 0" xyz="0 0 0"/>
      <geometry>
        <mesh filename="package://interbotix_xslocobot_descriptions/meshes/mobile_wx250s_meshes/mobile_wx250s_5_lower_forearm.stl" scale="0.001 0.001 0.001"/>
      </geometry>
    </collision>
    <inertial>
      <origin rpy="3.141592653589793 0 0" xyz="0.0374395000 0.0052225200 0"/>
      <mass value="0.220991"/>
      <inertia ixx="0.0000636900" ixy="-0.0000229200" ixz="0" iyy="0.0001677000" iyz="0" izz="0.0001834000"/>
    </inertial>
  </link>
  <joint name="wrist_angle" type="revolute">
    <axis xyz="0 1 0"/>
    <limit effort="5" lower="-1.7453292519943295" upper="2.1467549799530254" velocity="3.141592653589793"/>
    <origin rpy="0 0 0" xyz="0.075 0 0"/>
    <parent link="locobot/lower_forearm_link"/>
    <child link="locobot/wrist_link"/>
    <dynamics friction="0.1"/>
  </joint>
  <transmission name="trans_wrist_angle">
    <type>transmission_interface/SimpleTransmission</type>
    <joint name="wrist_angle">
      <hardwareInterface>hardware_interface/EffortJointInterface</hardwareInterface>
    </joint>
    <actuator name="wrist_angle_motor">
      <mechanicalReduction>1</mechanicalReduction>
    </actuator>
  </transmission>
  <link name="locobot/wrist_link">
    <visual>
      <origin rpy="0 0 1.5707963267948966" xyz="0 0 0"/>
      <geometry>
        <mesh filename="package://interbotix_xslocobot_descriptions/meshes/mobile_wx250s_meshes/mobile_wx250s_6_wrist.stl" scale="0.001 0.001 0.001"/>
      </geometry>
      <material name="interbotix_black"/>
    </visual>
    <collision>
      <origin rpy="0 0 1.5707963267948966" xyz="0 0 0"/>
      <geometry>
        <mesh filename="package://interbotix_xslocobot_descriptions/meshes/mobile_wx250s_meshes/mobile_wx250s_6_wrist.stl" scale="0.001 0.001 0.001"/>
      </geometry>
    </collision>
    <inertial>
      <origin rpy="0 0 1.5707963267948966" xyz="0.0423600000 -0.0000106630 0.0105770000"/>
      <mass value="0.084957"/>
      <inertia ixx="0.0000308200" ixy="0.0000000191" ixz="0.0000000023" iyy="0.0000282200" iyz="0.0000025481" izz="0.0000315200"/>
    </inertial>
  </link>
  <joint name="wrist_rotate" type="revolute">
    <axis xyz="1 0 0"/>
    <limit effort="1" lower="-3.141592653589793" upper="3.141592653589793" velocity="3.141592653589793"/>
    <origin rpy="0 0 0" xyz="0.065 0 0"/>
    <parent link="locobot/wrist_link"/>
    <child link="locobot/gripper_link"/>
    <dynamics friction="0.1"/>
  </joint>
  <transmission name="trans_wrist_rotate">
    <type>transmission_interface/SimpleTransmission</type>
    <joint name="wrist_rotate">
      <hardwareInterface>hardware_interface/EffortJointInterface</hardwareInterface>
    </joint>
    <actuator name="wrist_rotate_motor">
      <mechanicalReduction>1</mechanicalReduction>
    </actuator>
  </transmission>
  <link name="locobot/gripper_link">
    <visual>
      <origin rpy="0 0 1.5707963267948966" xyz="-0.02 0 0"/>
      <geometry>
        <mesh filename="package://interbotix_xslocobot_descriptions/meshes/mobile_wx250s_meshes/mobile_wx250s_7_gripper.stl" scale="0.001 0.001 0.001"/>
      </geometry>
      <material name="interbotix_black"/>
    </visual>
    <collision>
      <origin rpy="0 0 1.5707963267948966" xyz="-0.02 0 0"/>
      <geometry>
        <mesh filename="package://interbotix_xslocobot_descriptions/meshes/mobile_wx250s_meshes/mobile_wx250s_7_gripper.stl" scale="0.001 0.001 0.001"/>
      </geometry>
    </collision>
    <inertial>
      <origin rpy="0 0 1.5707963267948966" xyz="0.0216310000 0.0000002516 0.0114100000"/>
      <mass value="0.072885"/>
      <inertia ixx="0.0000253700" ixy="0.0000000000" ixz="0.0000000000" iyy="0.0000183600" iyz="0.0000004340" izz="0.0000167400"/>
    </inertial>
  </link>
  <joint name="ee_arm" type="fixed">
    <axis xyz="1 0 0"/>
    <origin rpy="0 0 0" xyz="0.043 0 0"/>
    <parent link="locobot/gripper_link"/>
    <child link="locobot/ee_arm_link"/>
  </joint>
  <link name="locobot/ee_arm_link">
    <inertial>
      <mass value="0.001"/>
      <inertia ixx="0.001" ixy="0" ixz="0" iyy="0.001" iyz="0" izz="0.001"/>
    </inertial>
  </link>
  <joint name="gripper" type="continuous">
    <axis xyz="1 0 0"/>
    <limit effort="1" velocity="3.141592653589793"/>
    <origin rpy="0 0 0" xyz="0.0055 0 0"/>
    <parent link="locobot/ee_arm_link"/>
    <child link="locobot/gripper_prop_link"/>
    <dynamics friction="0.1"/>
  </joint>
  <transmission name="trans_gripper">
    <type>transmission_interface/SimpleTransmission</type>
    <joint name="gripper">
      <hardwareInterface>hardware_interface/EffortJointInterface</hardwareInterface>
    </joint>
    <actuator name="gripper_motor">
      <mechanicalReduction>1</mechanicalReduction>
    </actuator>
  </transmission>
  <link name="locobot/gripper_prop_link">
    <visual>
      <origin rpy="0 0 1.5707963267948966" xyz="-0.0685 0 0"/>
      <geometry>
        <mesh filename="package://interbotix_xslocobot_descriptions/meshes/mobile_wx250s_meshes/mobile_wx250s_8_gripper_prop.stl" scale="0.001 0.001 0.001"/>
      </geometry>
      <material name="interbotix_black"/>
    </visual>
    <collision>
      <origin rpy="0 0 1.5707963267948966" xyz="-0.0685 0 0"/>
      <geometry>
        <mesh filename="package://interbotix_xslocobot_descriptions/meshes/mobile_wx250s_meshes/mobile_wx250s_8_gripper_prop.stl" scale="0.001 0.001 0.001"/>
      </geometry>
    </collision>
    <inertial>
      <origin rpy="0 0 1.5707963267948966" xyz="0.0008460000 -0.0000016817 0.0000420000"/>
      <mass value="0.00434"/>
      <inertia ixx="0.0000005923" ixy="0.0000000000" ixz="0.0000003195" iyy="0.0000011156" iyz="-0.0000000004" izz="0.0000005743"/>
    </inertial>
  </link>
  <joint name="ar_tag" type="fixed">
    <axis xyz="0 0 0"/>
    <origin rpy="0 0 0" xyz="-0.017 0 0.04155"/>
    <parent link="locobot/ee_arm_link"/>
    <child link="locobot/ar_tag_link"/>
  </joint>
  <link name="locobot/ar_tag_link">
    <visual>
      <origin rpy="0 0 0" xyz="0 0 0"/>
      <geometry>
        <mesh filename="package://interbotix_xslocobot_descriptions/meshes/mobile_wx250s_meshes/mobile_wx250s_11_ar_tag.stl" scale="0.001 0.001 0.001"/>
      </geometry>
      <material name="interbotix_black"/>
    </visual>
    <collision>
      <origin rpy="0 0 0" xyz="0 0 0"/>
      <geometry>
        <mesh filename="package://interbotix_xslocobot_descriptions/meshes/mobile_wx250s_meshes/mobile_wx250s_11_ar_tag.stl" scale="0.001 0.001 0.001"/>
      </geometry>
    </collision>
    <inertial>
      <origin rpy="0 0 0" xyz="0 0 -0.00315"/>
      <mass value="0.016507"/>
      <inertia ixx="0.000003084" ixy="0" ixz="0" iyy="0.000003084" iyz="0" izz="0.000006059"/>
    </inertial>
  </link>
  <!-- If the gripper bar is being used, then also add the gripper bar -->
</robot>
